{
 "cells": [
  {
   "cell_type": "markdown",
   "metadata": {},
   "source": [
    "# Deep Neural Network for MNIST Classification\n",
    "\n",
    "We'll apply all the knowledge from the lectures in this section to write a deep neural network. The problem we've chosen is referred to as the \"Hello World\" of deep learning because for most students it is the first deep learning algorithm they see.\n",
    "\n",
    "The dataset is called MNIST and refers to handwritten digit recognition. You can find more about it on Yann LeCun's website (Director of AI Research, Facebook). He is one of the pioneers of what we've been talking about and of more complex approaches that are widely used today, such as covolutional neural networks (CNNs). \n",
    "\n",
    "The dataset provides 70,000 images (28x28 pixels) of handwritten digits (1 digit per image). \n",
    "\n",
    "The goal is to write an algorithm that detects which digit is written. Since there are only 10 digits (0, 1, 2, 3, 4, 5, 6, 7, 8, 9), this is a classification problem with 10 classes. \n",
    "\n",
    "Our goal would be to build a neural network with 2 hidden layers."
   ]
  },
  {
   "cell_type": "markdown",
   "metadata": {},
   "source": [
    "## Import the relevant packages"
   ]
  },
  {
   "cell_type": "code",
   "execution_count": 5,
   "metadata": {},
   "outputs": [],
   "source": [
    "import tensorflow as tf"
   ]
  },
  {
   "cell_type": "code",
   "execution_count": 6,
   "metadata": {},
   "outputs": [
    {
     "data": {
      "text/plain": [
       "'2.0.0'"
      ]
     },
     "execution_count": 6,
     "metadata": {},
     "output_type": "execute_result"
    }
   ],
   "source": [
    "tf.__version__"
   ]
  },
  {
   "cell_type": "code",
   "execution_count": null,
   "metadata": {},
   "outputs": [
    {
     "name": "stderr",
     "output_type": "stream",
     "text": [
      "ERROR:root:Internal Python error in the inspect module.\n",
      "Below is the traceback from this internal error.\n",
      "\n",
      "ERROR:root:Internal Python error in the inspect module.\n",
      "Below is the traceback from this internal error.\n",
      "\n",
      "ERROR:root:Internal Python error in the inspect module.\n",
      "Below is the traceback from this internal error.\n",
      "\n"
     ]
    },
    {
     "name": "stdout",
     "output_type": "stream",
     "text": [
      "ERROR! Session/line number was not unique in database. History logging moved to new session 187\n",
      "Traceback (most recent call last):\n",
      "  File \"C:\\Users\\VYSHNAVI\\anaconda3\\envs\\vedadri\\lib\\site-packages\\IPython\\core\\interactiveshell.py\", line 3441, in run_code\n",
      "    exec(code_obj, self.user_global_ns, self.user_ns)\n",
      "  File \"C:\\Users\\VYSHNAVI\\AppData\\Local\\Temp/ipykernel_15436/3867888914.py\", line 4, in <module>\n",
      "    import tensorflow_datasets as tfds\n",
      "  File \"C:\\Users\\VYSHNAVI\\anaconda3\\envs\\vedadri\\lib\\site-packages\\tensorflow_datasets\\__init__.py\", line 53, in <module>\n",
      "    from tensorflow_datasets import d4rl\n",
      "  File \"C:\\Users\\VYSHNAVI\\anaconda3\\envs\\vedadri\\lib\\site-packages\\tensorflow_datasets\\d4rl\\__init__.py\", line 17, in <module>\n",
      "    from tensorflow_datasets.d4rl.d4rl_mujoco_ant import D4rlMujocoAnt\n",
      "  File \"C:\\Users\\VYSHNAVI\\anaconda3\\envs\\vedadri\\lib\\site-packages\\tensorflow_datasets\\d4rl\\d4rl_mujoco_ant\\__init__.py\", line 18, in <module>\n",
      "    from tensorflow_datasets.d4rl.d4rl_mujoco_ant.d4rl_mujoco_ant import D4rlMujocoAnt\n",
      "  File \"C:\\Users\\VYSHNAVI\\anaconda3\\envs\\vedadri\\lib\\site-packages\\tensorflow_datasets\\d4rl\\d4rl_mujoco_ant\\d4rl_mujoco_ant.py\", line 20, in <module>\n",
      "    from tensorflow_datasets.d4rl import mujoco_dataset\n",
      "  File \"C:\\Users\\VYSHNAVI\\anaconda3\\envs\\vedadri\\lib\\site-packages\\tensorflow_datasets\\d4rl\\mujoco_dataset.py\", line 22, in <module>\n",
      "    from tensorflow_datasets.d4rl import dataset_utils\n",
      "  File \"C:\\Users\\VYSHNAVI\\anaconda3\\envs\\vedadri\\lib\\site-packages\\tensorflow_datasets\\d4rl\\dataset_utils.py\", line 21, in <module>\n",
      "    from tensorflow.io import gfile\n",
      "ModuleNotFoundError: No module named 'tensorflow.io'\n",
      "\n",
      "During handling of the above exception, another exception occurred:\n",
      "\n",
      "Traceback (most recent call last):\n",
      "  File \"C:\\Users\\VYSHNAVI\\anaconda3\\envs\\vedadri\\lib\\site-packages\\IPython\\core\\interactiveshell.py\", line 2061, in showtraceback\n",
      "    stb = value._render_traceback_()\n",
      "AttributeError: 'ModuleNotFoundError' object has no attribute '_render_traceback_'\n",
      "\n",
      "During handling of the above exception, another exception occurred:\n",
      "\n",
      "Traceback (most recent call last):\n",
      "  File \"C:\\Users\\VYSHNAVI\\anaconda3\\envs\\vedadri\\lib\\site-packages\\IPython\\core\\ultratb.py\", line 1101, in get_records\n",
      "    return _fixed_getinnerframes(etb, number_of_lines_of_context, tb_offset)\n",
      "  File \"C:\\Users\\VYSHNAVI\\anaconda3\\envs\\vedadri\\lib\\site-packages\\IPython\\core\\ultratb.py\", line 248, in wrapped\n",
      "    return f(*args, **kwargs)\n",
      "  File \"C:\\Users\\VYSHNAVI\\anaconda3\\envs\\vedadri\\lib\\site-packages\\IPython\\core\\ultratb.py\", line 281, in _fixed_getinnerframes\n",
      "    records = fix_frame_records_filenames(inspect.getinnerframes(etb, context))\n",
      "  File \"C:\\Users\\VYSHNAVI\\anaconda3\\envs\\vedadri\\lib\\inspect.py\", line 1502, in getinnerframes\n",
      "    frameinfo = (tb.tb_frame,) + getframeinfo(tb, context)\n",
      "  File \"C:\\Users\\VYSHNAVI\\anaconda3\\envs\\vedadri\\lib\\inspect.py\", line 1460, in getframeinfo\n",
      "    filename = getsourcefile(frame) or getfile(frame)\n",
      "  File \"C:\\Users\\VYSHNAVI\\anaconda3\\envs\\vedadri\\lib\\inspect.py\", line 696, in getsourcefile\n",
      "    if getattr(getmodule(object, filename), '__loader__', None) is not None:\n",
      "  File \"C:\\Users\\VYSHNAVI\\anaconda3\\envs\\vedadri\\lib\\inspect.py\", line 733, in getmodule\n",
      "    if ismodule(module) and hasattr(module, '__file__'):\n",
      "  File \"C:\\Users\\VYSHNAVI\\anaconda3\\envs\\vedadri\\lib\\site-packages\\tensorflow\\__init__.py\", line 50, in __getattr__\n",
      "    module = self._load()\n",
      "  File \"C:\\Users\\VYSHNAVI\\anaconda3\\envs\\vedadri\\lib\\site-packages\\tensorflow\\__init__.py\", line 44, in _load\n",
      "    module = _importlib.import_module(self.__name__)\n",
      "  File \"C:\\Users\\VYSHNAVI\\anaconda3\\envs\\vedadri\\lib\\importlib\\__init__.py\", line 127, in import_module\n",
      "    return _bootstrap._gcd_import(name[level:], package, level)\n",
      "  File \"<frozen importlib._bootstrap>\", line 1006, in _gcd_import\n",
      "  File \"<frozen importlib._bootstrap>\", line 983, in _find_and_load\n",
      "  File \"<frozen importlib._bootstrap>\", line 965, in _find_and_load_unlocked\n",
      "ModuleNotFoundError: No module named 'tensorflow_core.estimator'\n",
      "Traceback (most recent call last):\n",
      "  File \"C:\\Users\\VYSHNAVI\\anaconda3\\envs\\vedadri\\lib\\site-packages\\IPython\\core\\interactiveshell.py\", line 3441, in run_code\n",
      "    exec(code_obj, self.user_global_ns, self.user_ns)\n",
      "  File \"C:\\Users\\VYSHNAVI\\AppData\\Local\\Temp/ipykernel_15436/3867888914.py\", line 4, in <module>\n",
      "    import tensorflow_datasets as tfds\n",
      "  File \"C:\\Users\\VYSHNAVI\\anaconda3\\envs\\vedadri\\lib\\site-packages\\tensorflow_datasets\\__init__.py\", line 53, in <module>\n",
      "    from tensorflow_datasets import d4rl\n",
      "  File \"C:\\Users\\VYSHNAVI\\anaconda3\\envs\\vedadri\\lib\\site-packages\\tensorflow_datasets\\d4rl\\__init__.py\", line 17, in <module>\n",
      "    from tensorflow_datasets.d4rl.d4rl_mujoco_ant import D4rlMujocoAnt\n",
      "  File \"C:\\Users\\VYSHNAVI\\anaconda3\\envs\\vedadri\\lib\\site-packages\\tensorflow_datasets\\d4rl\\d4rl_mujoco_ant\\__init__.py\", line 18, in <module>\n",
      "    from tensorflow_datasets.d4rl.d4rl_mujoco_ant.d4rl_mujoco_ant import D4rlMujocoAnt\n",
      "  File \"C:\\Users\\VYSHNAVI\\anaconda3\\envs\\vedadri\\lib\\site-packages\\tensorflow_datasets\\d4rl\\d4rl_mujoco_ant\\d4rl_mujoco_ant.py\", line 20, in <module>\n",
      "    from tensorflow_datasets.d4rl import mujoco_dataset\n",
      "  File \"C:\\Users\\VYSHNAVI\\anaconda3\\envs\\vedadri\\lib\\site-packages\\tensorflow_datasets\\d4rl\\mujoco_dataset.py\", line 22, in <module>\n",
      "    from tensorflow_datasets.d4rl import dataset_utils\n",
      "  File \"C:\\Users\\VYSHNAVI\\anaconda3\\envs\\vedadri\\lib\\site-packages\\tensorflow_datasets\\d4rl\\dataset_utils.py\", line 21, in <module>\n",
      "    from tensorflow.io import gfile\n",
      "ModuleNotFoundError: No module named 'tensorflow.io'\n",
      "\n",
      "During handling of the above exception, another exception occurred:\n",
      "\n",
      "Traceback (most recent call last):\n",
      "  File \"C:\\Users\\VYSHNAVI\\anaconda3\\envs\\vedadri\\lib\\site-packages\\IPython\\core\\interactiveshell.py\", line 2061, in showtraceback\n",
      "    stb = value._render_traceback_()\n",
      "AttributeError: 'ModuleNotFoundError' object has no attribute '_render_traceback_'\n",
      "\n",
      "During handling of the above exception, another exception occurred:\n",
      "\n",
      "Traceback (most recent call last):\n",
      "  File \"C:\\Users\\VYSHNAVI\\anaconda3\\envs\\vedadri\\lib\\site-packages\\IPython\\core\\interactiveshell.py\", line 3361, in run_ast_nodes\n",
      "    if (await self.run_code(code, result,  async_=asy)):\n",
      "  File \"C:\\Users\\VYSHNAVI\\anaconda3\\envs\\vedadri\\lib\\site-packages\\IPython\\core\\interactiveshell.py\", line 3458, in run_code\n",
      "    self.showtraceback(running_compiled_code=True)\n",
      "  File \"C:\\Users\\VYSHNAVI\\anaconda3\\envs\\vedadri\\lib\\site-packages\\IPython\\core\\interactiveshell.py\", line 2064, in showtraceback\n",
      "    value, tb, tb_offset=tb_offset)\n",
      "  File \"C:\\Users\\VYSHNAVI\\anaconda3\\envs\\vedadri\\lib\\site-packages\\IPython\\core\\ultratb.py\", line 1368, in structured_traceback\n",
      "    self, etype, value, tb, tb_offset, number_of_lines_of_context)\n",
      "  File \"C:\\Users\\VYSHNAVI\\anaconda3\\envs\\vedadri\\lib\\site-packages\\IPython\\core\\ultratb.py\", line 1268, in structured_traceback\n",
      "    self, etype, value, tb, tb_offset, number_of_lines_of_context\n",
      "  File \"C:\\Users\\VYSHNAVI\\anaconda3\\envs\\vedadri\\lib\\site-packages\\IPython\\core\\ultratb.py\", line 1125, in structured_traceback\n",
      "    tb_offset)\n",
      "  File \"C:\\Users\\VYSHNAVI\\anaconda3\\envs\\vedadri\\lib\\site-packages\\IPython\\core\\ultratb.py\", line 1082, in format_exception_as_a_whole\n",
      "    last_unique, recursion_repeat = find_recursion(orig_etype, evalue, records)\n",
      "  File \"C:\\Users\\VYSHNAVI\\anaconda3\\envs\\vedadri\\lib\\site-packages\\IPython\\core\\ultratb.py\", line 382, in find_recursion\n",
      "    return len(records), 0\n",
      "TypeError: object of type 'NoneType' has no len()\n",
      "\n",
      "During handling of the above exception, another exception occurred:\n",
      "\n",
      "Traceback (most recent call last):\n",
      "  File \"C:\\Users\\VYSHNAVI\\anaconda3\\envs\\vedadri\\lib\\site-packages\\IPython\\core\\interactiveshell.py\", line 2061, in showtraceback\n",
      "    stb = value._render_traceback_()\n",
      "AttributeError: 'TypeError' object has no attribute '_render_traceback_'\n",
      "\n",
      "During handling of the above exception, another exception occurred:\n",
      "\n",
      "Traceback (most recent call last):\n",
      "  File \"C:\\Users\\VYSHNAVI\\anaconda3\\envs\\vedadri\\lib\\site-packages\\IPython\\core\\ultratb.py\", line 1101, in get_records\n",
      "    return _fixed_getinnerframes(etb, number_of_lines_of_context, tb_offset)\n",
      "  File \"C:\\Users\\VYSHNAVI\\anaconda3\\envs\\vedadri\\lib\\site-packages\\IPython\\core\\ultratb.py\", line 248, in wrapped\n",
      "    return f(*args, **kwargs)\n",
      "  File \"C:\\Users\\VYSHNAVI\\anaconda3\\envs\\vedadri\\lib\\site-packages\\IPython\\core\\ultratb.py\", line 281, in _fixed_getinnerframes\n",
      "    records = fix_frame_records_filenames(inspect.getinnerframes(etb, context))\n",
      "  File \"C:\\Users\\VYSHNAVI\\anaconda3\\envs\\vedadri\\lib\\inspect.py\", line 1502, in getinnerframes\n",
      "    frameinfo = (tb.tb_frame,) + getframeinfo(tb, context)\n",
      "  File \"C:\\Users\\VYSHNAVI\\anaconda3\\envs\\vedadri\\lib\\inspect.py\", line 1460, in getframeinfo\n",
      "    filename = getsourcefile(frame) or getfile(frame)\n",
      "  File \"C:\\Users\\VYSHNAVI\\anaconda3\\envs\\vedadri\\lib\\inspect.py\", line 696, in getsourcefile\n",
      "    if getattr(getmodule(object, filename), '__loader__', None) is not None:\n",
      "  File \"C:\\Users\\VYSHNAVI\\anaconda3\\envs\\vedadri\\lib\\inspect.py\", line 733, in getmodule\n",
      "    if ismodule(module) and hasattr(module, '__file__'):\n",
      "  File \"C:\\Users\\VYSHNAVI\\anaconda3\\envs\\vedadri\\lib\\site-packages\\tensorflow\\__init__.py\", line 50, in __getattr__\n",
      "    module = self._load()\n",
      "  File \"C:\\Users\\VYSHNAVI\\anaconda3\\envs\\vedadri\\lib\\site-packages\\tensorflow\\__init__.py\", line 44, in _load\n",
      "    module = _importlib.import_module(self.__name__)\n",
      "  File \"C:\\Users\\VYSHNAVI\\anaconda3\\envs\\vedadri\\lib\\importlib\\__init__.py\", line 127, in import_module\n",
      "    return _bootstrap._gcd_import(name[level:], package, level)\n",
      "  File \"<frozen importlib._bootstrap>\", line 1006, in _gcd_import\n",
      "  File \"<frozen importlib._bootstrap>\", line 983, in _find_and_load\n",
      "  File \"<frozen importlib._bootstrap>\", line 965, in _find_and_load_unlocked\n",
      "ModuleNotFoundError: No module named 'tensorflow_core.estimator'\n",
      "Traceback (most recent call last):\n",
      "  File \"C:\\Users\\VYSHNAVI\\anaconda3\\envs\\vedadri\\lib\\site-packages\\IPython\\core\\interactiveshell.py\", line 3441, in run_code\n",
      "    exec(code_obj, self.user_global_ns, self.user_ns)\n",
      "  File \"C:\\Users\\VYSHNAVI\\AppData\\Local\\Temp/ipykernel_15436/3867888914.py\", line 4, in <module>\n",
      "    import tensorflow_datasets as tfds\n",
      "  File \"C:\\Users\\VYSHNAVI\\anaconda3\\envs\\vedadri\\lib\\site-packages\\tensorflow_datasets\\__init__.py\", line 53, in <module>\n",
      "    from tensorflow_datasets import d4rl\n",
      "  File \"C:\\Users\\VYSHNAVI\\anaconda3\\envs\\vedadri\\lib\\site-packages\\tensorflow_datasets\\d4rl\\__init__.py\", line 17, in <module>\n",
      "    from tensorflow_datasets.d4rl.d4rl_mujoco_ant import D4rlMujocoAnt\n",
      "  File \"C:\\Users\\VYSHNAVI\\anaconda3\\envs\\vedadri\\lib\\site-packages\\tensorflow_datasets\\d4rl\\d4rl_mujoco_ant\\__init__.py\", line 18, in <module>\n",
      "    from tensorflow_datasets.d4rl.d4rl_mujoco_ant.d4rl_mujoco_ant import D4rlMujocoAnt\n",
      "  File \"C:\\Users\\VYSHNAVI\\anaconda3\\envs\\vedadri\\lib\\site-packages\\tensorflow_datasets\\d4rl\\d4rl_mujoco_ant\\d4rl_mujoco_ant.py\", line 20, in <module>\n",
      "    from tensorflow_datasets.d4rl import mujoco_dataset\n",
      "  File \"C:\\Users\\VYSHNAVI\\anaconda3\\envs\\vedadri\\lib\\site-packages\\tensorflow_datasets\\d4rl\\mujoco_dataset.py\", line 22, in <module>\n",
      "    from tensorflow_datasets.d4rl import dataset_utils\n",
      "  File \"C:\\Users\\VYSHNAVI\\anaconda3\\envs\\vedadri\\lib\\site-packages\\tensorflow_datasets\\d4rl\\dataset_utils.py\", line 21, in <module>\n",
      "    from tensorflow.io import gfile\n",
      "ModuleNotFoundError: No module named 'tensorflow.io'\n",
      "\n",
      "During handling of the above exception, another exception occurred:\n",
      "\n",
      "Traceback (most recent call last):\n",
      "  File \"C:\\Users\\VYSHNAVI\\anaconda3\\envs\\vedadri\\lib\\site-packages\\IPython\\core\\interactiveshell.py\", line 2061, in showtraceback\n",
      "    stb = value._render_traceback_()\n",
      "AttributeError: 'ModuleNotFoundError' object has no attribute '_render_traceback_'\n",
      "\n",
      "During handling of the above exception, another exception occurred:\n",
      "\n",
      "Traceback (most recent call last):\n",
      "  File \"C:\\Users\\VYSHNAVI\\anaconda3\\envs\\vedadri\\lib\\site-packages\\IPython\\core\\interactiveshell.py\", line 3361, in run_ast_nodes\n",
      "    if (await self.run_code(code, result,  async_=asy)):\n",
      "  File \"C:\\Users\\VYSHNAVI\\anaconda3\\envs\\vedadri\\lib\\site-packages\\IPython\\core\\interactiveshell.py\", line 3458, in run_code\n",
      "    self.showtraceback(running_compiled_code=True)\n",
      "  File \"C:\\Users\\VYSHNAVI\\anaconda3\\envs\\vedadri\\lib\\site-packages\\IPython\\core\\interactiveshell.py\", line 2064, in showtraceback\n",
      "    value, tb, tb_offset=tb_offset)\n",
      "  File \"C:\\Users\\VYSHNAVI\\anaconda3\\envs\\vedadri\\lib\\site-packages\\IPython\\core\\ultratb.py\", line 1368, in structured_traceback\n",
      "    self, etype, value, tb, tb_offset, number_of_lines_of_context)\n",
      "  File \"C:\\Users\\VYSHNAVI\\anaconda3\\envs\\vedadri\\lib\\site-packages\\IPython\\core\\ultratb.py\", line 1268, in structured_traceback\n",
      "    self, etype, value, tb, tb_offset, number_of_lines_of_context\n",
      "  File \"C:\\Users\\VYSHNAVI\\anaconda3\\envs\\vedadri\\lib\\site-packages\\IPython\\core\\ultratb.py\", line 1125, in structured_traceback\n",
      "    tb_offset)\n",
      "  File \"C:\\Users\\VYSHNAVI\\anaconda3\\envs\\vedadri\\lib\\site-packages\\IPython\\core\\ultratb.py\", line 1082, in format_exception_as_a_whole\n",
      "    last_unique, recursion_repeat = find_recursion(orig_etype, evalue, records)\n",
      "  File \"C:\\Users\\VYSHNAVI\\anaconda3\\envs\\vedadri\\lib\\site-packages\\IPython\\core\\ultratb.py\", line 382, in find_recursion\n",
      "    return len(records), 0\n",
      "TypeError: object of type 'NoneType' has no len()\n",
      "\n",
      "During handling of the above exception, another exception occurred:\n",
      "\n",
      "Traceback (most recent call last):\n",
      "  File \"C:\\Users\\VYSHNAVI\\anaconda3\\envs\\vedadri\\lib\\site-packages\\IPython\\core\\interactiveshell.py\", line 2061, in showtraceback\n",
      "    stb = value._render_traceback_()\n",
      "AttributeError: 'TypeError' object has no attribute '_render_traceback_'\n",
      "\n",
      "During handling of the above exception, another exception occurred:\n",
      "\n",
      "Traceback (most recent call last):\n",
      "  File \"C:\\Users\\VYSHNAVI\\anaconda3\\envs\\vedadri\\lib\\site-packages\\IPython\\core\\interactiveshell.py\", line 2944, in _run_cell\n",
      "    return runner(coro)\n",
      "  File \"C:\\Users\\VYSHNAVI\\anaconda3\\envs\\vedadri\\lib\\site-packages\\IPython\\core\\async_helpers.py\", line 68, in _pseudo_sync_runner\n",
      "    coro.send(None)\n",
      "  File \"C:\\Users\\VYSHNAVI\\anaconda3\\envs\\vedadri\\lib\\site-packages\\IPython\\core\\interactiveshell.py\", line 3170, in run_cell_async\n",
      "    interactivity=interactivity, compiler=compiler, result=result)\n",
      "  File \"C:\\Users\\VYSHNAVI\\anaconda3\\envs\\vedadri\\lib\\site-packages\\IPython\\core\\interactiveshell.py\", line 3380, in run_ast_nodes\n",
      "    self.showtraceback()\n",
      "  File \"C:\\Users\\VYSHNAVI\\anaconda3\\envs\\vedadri\\lib\\site-packages\\IPython\\core\\interactiveshell.py\", line 2064, in showtraceback\n",
      "    value, tb, tb_offset=tb_offset)\n",
      "  File \"C:\\Users\\VYSHNAVI\\anaconda3\\envs\\vedadri\\lib\\site-packages\\IPython\\core\\ultratb.py\", line 1368, in structured_traceback\n",
      "    self, etype, value, tb, tb_offset, number_of_lines_of_context)\n",
      "  File \"C:\\Users\\VYSHNAVI\\anaconda3\\envs\\vedadri\\lib\\site-packages\\IPython\\core\\ultratb.py\", line 1268, in structured_traceback\n",
      "    self, etype, value, tb, tb_offset, number_of_lines_of_context\n",
      "  File \"C:\\Users\\VYSHNAVI\\anaconda3\\envs\\vedadri\\lib\\site-packages\\IPython\\core\\ultratb.py\", line 1143, in structured_traceback\n",
      "    chained_exceptions_tb_offset)\n",
      "  File \"C:\\Users\\VYSHNAVI\\anaconda3\\envs\\vedadri\\lib\\site-packages\\IPython\\core\\ultratb.py\", line 1082, in format_exception_as_a_whole\n",
      "    last_unique, recursion_repeat = find_recursion(orig_etype, evalue, records)\n",
      "  File \"C:\\Users\\VYSHNAVI\\anaconda3\\envs\\vedadri\\lib\\site-packages\\IPython\\core\\ultratb.py\", line 382, in find_recursion\n",
      "    return len(records), 0\n",
      "TypeError: object of type 'NoneType' has no len()\n",
      "\n",
      "During handling of the above exception, another exception occurred:\n",
      "\n",
      "Traceback (most recent call last):\n",
      "  File \"C:\\Users\\VYSHNAVI\\anaconda3\\envs\\vedadri\\lib\\site-packages\\IPython\\core\\interactiveshell.py\", line 2061, in showtraceback\n",
      "    stb = value._render_traceback_()\n",
      "AttributeError: 'TypeError' object has no attribute '_render_traceback_'\n",
      "\n",
      "During handling of the above exception, another exception occurred:\n",
      "\n",
      "Traceback (most recent call last):\n",
      "  File \"C:\\Users\\VYSHNAVI\\anaconda3\\envs\\vedadri\\lib\\site-packages\\IPython\\core\\ultratb.py\", line 1101, in get_records\n",
      "    return _fixed_getinnerframes(etb, number_of_lines_of_context, tb_offset)\n",
      "  File \"C:\\Users\\VYSHNAVI\\anaconda3\\envs\\vedadri\\lib\\site-packages\\IPython\\core\\ultratb.py\", line 248, in wrapped\n",
      "    return f(*args, **kwargs)\n",
      "  File \"C:\\Users\\VYSHNAVI\\anaconda3\\envs\\vedadri\\lib\\site-packages\\IPython\\core\\ultratb.py\", line 281, in _fixed_getinnerframes\n",
      "    records = fix_frame_records_filenames(inspect.getinnerframes(etb, context))\n",
      "  File \"C:\\Users\\VYSHNAVI\\anaconda3\\envs\\vedadri\\lib\\inspect.py\", line 1502, in getinnerframes\n",
      "    frameinfo = (tb.tb_frame,) + getframeinfo(tb, context)\n",
      "  File \"C:\\Users\\VYSHNAVI\\anaconda3\\envs\\vedadri\\lib\\inspect.py\", line 1460, in getframeinfo\n",
      "    filename = getsourcefile(frame) or getfile(frame)\n",
      "  File \"C:\\Users\\VYSHNAVI\\anaconda3\\envs\\vedadri\\lib\\inspect.py\", line 696, in getsourcefile\n",
      "    if getattr(getmodule(object, filename), '__loader__', None) is not None:\n",
      "  File \"C:\\Users\\VYSHNAVI\\anaconda3\\envs\\vedadri\\lib\\inspect.py\", line 733, in getmodule\n",
      "    if ismodule(module) and hasattr(module, '__file__'):\n",
      "  File \"C:\\Users\\VYSHNAVI\\anaconda3\\envs\\vedadri\\lib\\site-packages\\tensorflow\\__init__.py\", line 50, in __getattr__\n",
      "    module = self._load()\n",
      "  File \"C:\\Users\\VYSHNAVI\\anaconda3\\envs\\vedadri\\lib\\site-packages\\tensorflow\\__init__.py\", line 44, in _load\n",
      "    module = _importlib.import_module(self.__name__)\n",
      "  File \"C:\\Users\\VYSHNAVI\\anaconda3\\envs\\vedadri\\lib\\importlib\\__init__.py\", line 127, in import_module\n",
      "    return _bootstrap._gcd_import(name[level:], package, level)\n",
      "  File \"<frozen importlib._bootstrap>\", line 1006, in _gcd_import\n",
      "  File \"<frozen importlib._bootstrap>\", line 983, in _find_and_load\n",
      "  File \"<frozen importlib._bootstrap>\", line 965, in _find_and_load_unlocked\n",
      "ModuleNotFoundError: No module named 'tensorflow_core.estimator'\n"
     ]
    }
   ],
   "source": [
    "import numpy as np\n",
    "import tensorflow as tf\n",
    "\n",
    "import tensorflow_datasets as tfds"
   ]
  },
  {
   "cell_type": "markdown",
   "metadata": {},
   "source": [
    "## Data"
   ]
  },
  {
   "cell_type": "code",
   "execution_count": null,
   "metadata": {},
   "outputs": [
    {
     "name": "stderr",
     "output_type": "stream",
     "text": [
      "ERROR:root:Internal Python error in the inspect module.\n",
      "Below is the traceback from this internal error.\n",
      "\n",
      "ERROR:root:Internal Python error in the inspect module.\n",
      "Below is the traceback from this internal error.\n",
      "\n",
      "ERROR:root:Internal Python error in the inspect module.\n",
      "Below is the traceback from this internal error.\n",
      "\n"
     ]
    },
    {
     "name": "stdout",
     "output_type": "stream",
     "text": [
      "Traceback (most recent call last):\n",
      "  File \"C:\\Users\\VYSHNAVI\\anaconda3\\envs\\vedadri\\lib\\site-packages\\IPython\\core\\interactiveshell.py\", line 3441, in run_code\n",
      "    exec(code_obj, self.user_global_ns, self.user_ns)\n",
      "  File \"C:\\Users\\VYSHNAVI\\AppData\\Local\\Temp/ipykernel_15436/529325914.py\", line 1, in <module>\n",
      "    mnist_dataset, mnist_info = tfds.load(name='mnist', with_info=True, as_supervised=True)\n",
      "NameError: name 'tfds' is not defined\n",
      "\n",
      "During handling of the above exception, another exception occurred:\n",
      "\n",
      "Traceback (most recent call last):\n",
      "  File \"C:\\Users\\VYSHNAVI\\anaconda3\\envs\\vedadri\\lib\\site-packages\\IPython\\core\\interactiveshell.py\", line 2061, in showtraceback\n",
      "    stb = value._render_traceback_()\n",
      "AttributeError: 'NameError' object has no attribute '_render_traceback_'\n",
      "\n",
      "During handling of the above exception, another exception occurred:\n",
      "\n",
      "Traceback (most recent call last):\n",
      "  File \"C:\\Users\\VYSHNAVI\\anaconda3\\envs\\vedadri\\lib\\site-packages\\IPython\\core\\ultratb.py\", line 1101, in get_records\n",
      "    return _fixed_getinnerframes(etb, number_of_lines_of_context, tb_offset)\n",
      "  File \"C:\\Users\\VYSHNAVI\\anaconda3\\envs\\vedadri\\lib\\site-packages\\IPython\\core\\ultratb.py\", line 248, in wrapped\n",
      "    return f(*args, **kwargs)\n",
      "  File \"C:\\Users\\VYSHNAVI\\anaconda3\\envs\\vedadri\\lib\\site-packages\\IPython\\core\\ultratb.py\", line 281, in _fixed_getinnerframes\n",
      "    records = fix_frame_records_filenames(inspect.getinnerframes(etb, context))\n",
      "  File \"C:\\Users\\VYSHNAVI\\anaconda3\\envs\\vedadri\\lib\\inspect.py\", line 1502, in getinnerframes\n",
      "    frameinfo = (tb.tb_frame,) + getframeinfo(tb, context)\n",
      "  File \"C:\\Users\\VYSHNAVI\\anaconda3\\envs\\vedadri\\lib\\inspect.py\", line 1460, in getframeinfo\n",
      "    filename = getsourcefile(frame) or getfile(frame)\n",
      "  File \"C:\\Users\\VYSHNAVI\\anaconda3\\envs\\vedadri\\lib\\inspect.py\", line 696, in getsourcefile\n",
      "    if getattr(getmodule(object, filename), '__loader__', None) is not None:\n",
      "  File \"C:\\Users\\VYSHNAVI\\anaconda3\\envs\\vedadri\\lib\\inspect.py\", line 733, in getmodule\n",
      "    if ismodule(module) and hasattr(module, '__file__'):\n",
      "  File \"C:\\Users\\VYSHNAVI\\anaconda3\\envs\\vedadri\\lib\\site-packages\\tensorflow\\__init__.py\", line 50, in __getattr__\n",
      "    module = self._load()\n",
      "  File \"C:\\Users\\VYSHNAVI\\anaconda3\\envs\\vedadri\\lib\\site-packages\\tensorflow\\__init__.py\", line 44, in _load\n",
      "    module = _importlib.import_module(self.__name__)\n",
      "  File \"C:\\Users\\VYSHNAVI\\anaconda3\\envs\\vedadri\\lib\\importlib\\__init__.py\", line 127, in import_module\n",
      "    return _bootstrap._gcd_import(name[level:], package, level)\n",
      "  File \"<frozen importlib._bootstrap>\", line 1006, in _gcd_import\n",
      "  File \"<frozen importlib._bootstrap>\", line 983, in _find_and_load\n",
      "  File \"<frozen importlib._bootstrap>\", line 965, in _find_and_load_unlocked\n",
      "ModuleNotFoundError: No module named 'tensorflow_core.estimator'\n",
      "ERROR! Session/line number was not unique in database. History logging moved to new session 186\n",
      "Traceback (most recent call last):\n",
      "  File \"C:\\Users\\VYSHNAVI\\anaconda3\\envs\\vedadri\\lib\\site-packages\\IPython\\core\\interactiveshell.py\", line 3441, in run_code\n",
      "    exec(code_obj, self.user_global_ns, self.user_ns)\n",
      "  File \"C:\\Users\\VYSHNAVI\\AppData\\Local\\Temp/ipykernel_15436/529325914.py\", line 1, in <module>\n",
      "    mnist_dataset, mnist_info = tfds.load(name='mnist', with_info=True, as_supervised=True)\n",
      "NameError: name 'tfds' is not defined\n",
      "\n",
      "During handling of the above exception, another exception occurred:\n",
      "\n",
      "Traceback (most recent call last):\n",
      "  File \"C:\\Users\\VYSHNAVI\\anaconda3\\envs\\vedadri\\lib\\site-packages\\IPython\\core\\interactiveshell.py\", line 2061, in showtraceback\n",
      "    stb = value._render_traceback_()\n",
      "AttributeError: 'NameError' object has no attribute '_render_traceback_'\n",
      "\n",
      "During handling of the above exception, another exception occurred:\n",
      "\n",
      "Traceback (most recent call last):\n",
      "  File \"C:\\Users\\VYSHNAVI\\anaconda3\\envs\\vedadri\\lib\\site-packages\\IPython\\core\\interactiveshell.py\", line 3361, in run_ast_nodes\n",
      "    if (await self.run_code(code, result,  async_=asy)):\n",
      "  File \"C:\\Users\\VYSHNAVI\\anaconda3\\envs\\vedadri\\lib\\site-packages\\IPython\\core\\interactiveshell.py\", line 3458, in run_code\n",
      "    self.showtraceback(running_compiled_code=True)\n",
      "  File \"C:\\Users\\VYSHNAVI\\anaconda3\\envs\\vedadri\\lib\\site-packages\\IPython\\core\\interactiveshell.py\", line 2064, in showtraceback\n",
      "    value, tb, tb_offset=tb_offset)\n",
      "  File \"C:\\Users\\VYSHNAVI\\anaconda3\\envs\\vedadri\\lib\\site-packages\\IPython\\core\\ultratb.py\", line 1368, in structured_traceback\n",
      "    self, etype, value, tb, tb_offset, number_of_lines_of_context)\n",
      "  File \"C:\\Users\\VYSHNAVI\\anaconda3\\envs\\vedadri\\lib\\site-packages\\IPython\\core\\ultratb.py\", line 1268, in structured_traceback\n",
      "    self, etype, value, tb, tb_offset, number_of_lines_of_context\n",
      "  File \"C:\\Users\\VYSHNAVI\\anaconda3\\envs\\vedadri\\lib\\site-packages\\IPython\\core\\ultratb.py\", line 1125, in structured_traceback\n",
      "    tb_offset)\n",
      "  File \"C:\\Users\\VYSHNAVI\\anaconda3\\envs\\vedadri\\lib\\site-packages\\IPython\\core\\ultratb.py\", line 1082, in format_exception_as_a_whole\n",
      "    last_unique, recursion_repeat = find_recursion(orig_etype, evalue, records)\n",
      "  File \"C:\\Users\\VYSHNAVI\\anaconda3\\envs\\vedadri\\lib\\site-packages\\IPython\\core\\ultratb.py\", line 382, in find_recursion\n",
      "    return len(records), 0\n",
      "TypeError: object of type 'NoneType' has no len()\n",
      "\n",
      "During handling of the above exception, another exception occurred:\n",
      "\n",
      "Traceback (most recent call last):\n",
      "  File \"C:\\Users\\VYSHNAVI\\anaconda3\\envs\\vedadri\\lib\\site-packages\\IPython\\core\\interactiveshell.py\", line 2061, in showtraceback\n",
      "    stb = value._render_traceback_()\n",
      "AttributeError: 'TypeError' object has no attribute '_render_traceback_'\n",
      "\n",
      "During handling of the above exception, another exception occurred:\n",
      "\n",
      "Traceback (most recent call last):\n",
      "  File \"C:\\Users\\VYSHNAVI\\anaconda3\\envs\\vedadri\\lib\\site-packages\\IPython\\core\\ultratb.py\", line 1101, in get_records\n",
      "    return _fixed_getinnerframes(etb, number_of_lines_of_context, tb_offset)\n",
      "  File \"C:\\Users\\VYSHNAVI\\anaconda3\\envs\\vedadri\\lib\\site-packages\\IPython\\core\\ultratb.py\", line 248, in wrapped\n",
      "    return f(*args, **kwargs)\n",
      "  File \"C:\\Users\\VYSHNAVI\\anaconda3\\envs\\vedadri\\lib\\site-packages\\IPython\\core\\ultratb.py\", line 281, in _fixed_getinnerframes\n",
      "    records = fix_frame_records_filenames(inspect.getinnerframes(etb, context))\n",
      "  File \"C:\\Users\\VYSHNAVI\\anaconda3\\envs\\vedadri\\lib\\inspect.py\", line 1502, in getinnerframes\n",
      "    frameinfo = (tb.tb_frame,) + getframeinfo(tb, context)\n",
      "  File \"C:\\Users\\VYSHNAVI\\anaconda3\\envs\\vedadri\\lib\\inspect.py\", line 1460, in getframeinfo\n",
      "    filename = getsourcefile(frame) or getfile(frame)\n",
      "  File \"C:\\Users\\VYSHNAVI\\anaconda3\\envs\\vedadri\\lib\\inspect.py\", line 696, in getsourcefile\n",
      "    if getattr(getmodule(object, filename), '__loader__', None) is not None:\n",
      "  File \"C:\\Users\\VYSHNAVI\\anaconda3\\envs\\vedadri\\lib\\inspect.py\", line 733, in getmodule\n",
      "    if ismodule(module) and hasattr(module, '__file__'):\n",
      "  File \"C:\\Users\\VYSHNAVI\\anaconda3\\envs\\vedadri\\lib\\site-packages\\tensorflow\\__init__.py\", line 50, in __getattr__\n",
      "    module = self._load()\n",
      "  File \"C:\\Users\\VYSHNAVI\\anaconda3\\envs\\vedadri\\lib\\site-packages\\tensorflow\\__init__.py\", line 44, in _load\n",
      "    module = _importlib.import_module(self.__name__)\n",
      "  File \"C:\\Users\\VYSHNAVI\\anaconda3\\envs\\vedadri\\lib\\importlib\\__init__.py\", line 127, in import_module\n",
      "    return _bootstrap._gcd_import(name[level:], package, level)\n",
      "  File \"<frozen importlib._bootstrap>\", line 1006, in _gcd_import\n",
      "  File \"<frozen importlib._bootstrap>\", line 983, in _find_and_load\n",
      "  File \"<frozen importlib._bootstrap>\", line 965, in _find_and_load_unlocked\n",
      "ModuleNotFoundError: No module named 'tensorflow_core.estimator'\n",
      "Traceback (most recent call last):\n",
      "  File \"C:\\Users\\VYSHNAVI\\anaconda3\\envs\\vedadri\\lib\\site-packages\\IPython\\core\\interactiveshell.py\", line 3441, in run_code\n",
      "    exec(code_obj, self.user_global_ns, self.user_ns)\n",
      "  File \"C:\\Users\\VYSHNAVI\\AppData\\Local\\Temp/ipykernel_15436/529325914.py\", line 1, in <module>\n",
      "    mnist_dataset, mnist_info = tfds.load(name='mnist', with_info=True, as_supervised=True)\n",
      "NameError: name 'tfds' is not defined\n",
      "\n",
      "During handling of the above exception, another exception occurred:\n",
      "\n",
      "Traceback (most recent call last):\n",
      "  File \"C:\\Users\\VYSHNAVI\\anaconda3\\envs\\vedadri\\lib\\site-packages\\IPython\\core\\interactiveshell.py\", line 2061, in showtraceback\n",
      "    stb = value._render_traceback_()\n",
      "AttributeError: 'NameError' object has no attribute '_render_traceback_'\n",
      "\n",
      "During handling of the above exception, another exception occurred:\n",
      "\n",
      "Traceback (most recent call last):\n",
      "  File \"C:\\Users\\VYSHNAVI\\anaconda3\\envs\\vedadri\\lib\\site-packages\\IPython\\core\\interactiveshell.py\", line 3361, in run_ast_nodes\n",
      "    if (await self.run_code(code, result,  async_=asy)):\n",
      "  File \"C:\\Users\\VYSHNAVI\\anaconda3\\envs\\vedadri\\lib\\site-packages\\IPython\\core\\interactiveshell.py\", line 3458, in run_code\n",
      "    self.showtraceback(running_compiled_code=True)\n",
      "  File \"C:\\Users\\VYSHNAVI\\anaconda3\\envs\\vedadri\\lib\\site-packages\\IPython\\core\\interactiveshell.py\", line 2064, in showtraceback\n",
      "    value, tb, tb_offset=tb_offset)\n",
      "  File \"C:\\Users\\VYSHNAVI\\anaconda3\\envs\\vedadri\\lib\\site-packages\\IPython\\core\\ultratb.py\", line 1368, in structured_traceback\n",
      "    self, etype, value, tb, tb_offset, number_of_lines_of_context)\n",
      "  File \"C:\\Users\\VYSHNAVI\\anaconda3\\envs\\vedadri\\lib\\site-packages\\IPython\\core\\ultratb.py\", line 1268, in structured_traceback\n",
      "    self, etype, value, tb, tb_offset, number_of_lines_of_context\n",
      "  File \"C:\\Users\\VYSHNAVI\\anaconda3\\envs\\vedadri\\lib\\site-packages\\IPython\\core\\ultratb.py\", line 1125, in structured_traceback\n",
      "    tb_offset)\n",
      "  File \"C:\\Users\\VYSHNAVI\\anaconda3\\envs\\vedadri\\lib\\site-packages\\IPython\\core\\ultratb.py\", line 1082, in format_exception_as_a_whole\n",
      "    last_unique, recursion_repeat = find_recursion(orig_etype, evalue, records)\n",
      "  File \"C:\\Users\\VYSHNAVI\\anaconda3\\envs\\vedadri\\lib\\site-packages\\IPython\\core\\ultratb.py\", line 382, in find_recursion\n",
      "    return len(records), 0\n",
      "TypeError: object of type 'NoneType' has no len()\n",
      "\n",
      "During handling of the above exception, another exception occurred:\n",
      "\n",
      "Traceback (most recent call last):\n",
      "  File \"C:\\Users\\VYSHNAVI\\anaconda3\\envs\\vedadri\\lib\\site-packages\\IPython\\core\\interactiveshell.py\", line 2061, in showtraceback\n",
      "    stb = value._render_traceback_()\n",
      "AttributeError: 'TypeError' object has no attribute '_render_traceback_'\n",
      "\n",
      "During handling of the above exception, another exception occurred:\n",
      "\n",
      "Traceback (most recent call last):\n",
      "  File \"C:\\Users\\VYSHNAVI\\anaconda3\\envs\\vedadri\\lib\\site-packages\\IPython\\core\\interactiveshell.py\", line 2944, in _run_cell\n",
      "    return runner(coro)\n",
      "  File \"C:\\Users\\VYSHNAVI\\anaconda3\\envs\\vedadri\\lib\\site-packages\\IPython\\core\\async_helpers.py\", line 68, in _pseudo_sync_runner\n",
      "    coro.send(None)\n",
      "  File \"C:\\Users\\VYSHNAVI\\anaconda3\\envs\\vedadri\\lib\\site-packages\\IPython\\core\\interactiveshell.py\", line 3170, in run_cell_async\n",
      "    interactivity=interactivity, compiler=compiler, result=result)\n",
      "  File \"C:\\Users\\VYSHNAVI\\anaconda3\\envs\\vedadri\\lib\\site-packages\\IPython\\core\\interactiveshell.py\", line 3380, in run_ast_nodes\n",
      "    self.showtraceback()\n",
      "  File \"C:\\Users\\VYSHNAVI\\anaconda3\\envs\\vedadri\\lib\\site-packages\\IPython\\core\\interactiveshell.py\", line 2064, in showtraceback\n",
      "    value, tb, tb_offset=tb_offset)\n",
      "  File \"C:\\Users\\VYSHNAVI\\anaconda3\\envs\\vedadri\\lib\\site-packages\\IPython\\core\\ultratb.py\", line 1368, in structured_traceback\n",
      "    self, etype, value, tb, tb_offset, number_of_lines_of_context)\n",
      "  File \"C:\\Users\\VYSHNAVI\\anaconda3\\envs\\vedadri\\lib\\site-packages\\IPython\\core\\ultratb.py\", line 1268, in structured_traceback\n",
      "    self, etype, value, tb, tb_offset, number_of_lines_of_context\n",
      "  File \"C:\\Users\\VYSHNAVI\\anaconda3\\envs\\vedadri\\lib\\site-packages\\IPython\\core\\ultratb.py\", line 1143, in structured_traceback\n",
      "    chained_exceptions_tb_offset)\n",
      "  File \"C:\\Users\\VYSHNAVI\\anaconda3\\envs\\vedadri\\lib\\site-packages\\IPython\\core\\ultratb.py\", line 1082, in format_exception_as_a_whole\n",
      "    last_unique, recursion_repeat = find_recursion(orig_etype, evalue, records)\n",
      "  File \"C:\\Users\\VYSHNAVI\\anaconda3\\envs\\vedadri\\lib\\site-packages\\IPython\\core\\ultratb.py\", line 382, in find_recursion\n",
      "    return len(records), 0\n",
      "TypeError: object of type 'NoneType' has no len()\n",
      "\n",
      "During handling of the above exception, another exception occurred:\n",
      "\n",
      "Traceback (most recent call last):\n",
      "  File \"C:\\Users\\VYSHNAVI\\anaconda3\\envs\\vedadri\\lib\\site-packages\\IPython\\core\\interactiveshell.py\", line 2061, in showtraceback\n",
      "    stb = value._render_traceback_()\n",
      "AttributeError: 'TypeError' object has no attribute '_render_traceback_'\n",
      "\n",
      "During handling of the above exception, another exception occurred:\n",
      "\n",
      "Traceback (most recent call last):\n",
      "  File \"C:\\Users\\VYSHNAVI\\anaconda3\\envs\\vedadri\\lib\\site-packages\\IPython\\core\\ultratb.py\", line 1101, in get_records\n",
      "    return _fixed_getinnerframes(etb, number_of_lines_of_context, tb_offset)\n",
      "  File \"C:\\Users\\VYSHNAVI\\anaconda3\\envs\\vedadri\\lib\\site-packages\\IPython\\core\\ultratb.py\", line 248, in wrapped\n",
      "    return f(*args, **kwargs)\n",
      "  File \"C:\\Users\\VYSHNAVI\\anaconda3\\envs\\vedadri\\lib\\site-packages\\IPython\\core\\ultratb.py\", line 281, in _fixed_getinnerframes\n",
      "    records = fix_frame_records_filenames(inspect.getinnerframes(etb, context))\n",
      "  File \"C:\\Users\\VYSHNAVI\\anaconda3\\envs\\vedadri\\lib\\inspect.py\", line 1502, in getinnerframes\n",
      "    frameinfo = (tb.tb_frame,) + getframeinfo(tb, context)\n",
      "  File \"C:\\Users\\VYSHNAVI\\anaconda3\\envs\\vedadri\\lib\\inspect.py\", line 1460, in getframeinfo\n",
      "    filename = getsourcefile(frame) or getfile(frame)\n",
      "  File \"C:\\Users\\VYSHNAVI\\anaconda3\\envs\\vedadri\\lib\\inspect.py\", line 696, in getsourcefile\n",
      "    if getattr(getmodule(object, filename), '__loader__', None) is not None:\n",
      "  File \"C:\\Users\\VYSHNAVI\\anaconda3\\envs\\vedadri\\lib\\inspect.py\", line 733, in getmodule\n",
      "    if ismodule(module) and hasattr(module, '__file__'):\n",
      "  File \"C:\\Users\\VYSHNAVI\\anaconda3\\envs\\vedadri\\lib\\site-packages\\tensorflow\\__init__.py\", line 50, in __getattr__\n",
      "    module = self._load()\n",
      "  File \"C:\\Users\\VYSHNAVI\\anaconda3\\envs\\vedadri\\lib\\site-packages\\tensorflow\\__init__.py\", line 44, in _load\n",
      "    module = _importlib.import_module(self.__name__)\n",
      "  File \"C:\\Users\\VYSHNAVI\\anaconda3\\envs\\vedadri\\lib\\importlib\\__init__.py\", line 127, in import_module\n",
      "    return _bootstrap._gcd_import(name[level:], package, level)\n",
      "  File \"<frozen importlib._bootstrap>\", line 1006, in _gcd_import\n",
      "  File \"<frozen importlib._bootstrap>\", line 983, in _find_and_load\n",
      "  File \"<frozen importlib._bootstrap>\", line 965, in _find_and_load_unlocked\n",
      "ModuleNotFoundError: No module named 'tensorflow_core.estimator'\n"
     ]
    }
   ],
   "source": [
    "mnist_dataset, mnist_info = tfds.load(name='mnist', with_info=True, as_supervised=True)\n",
    "\n",
    "mnist_train, mnist_test = mnist_dataset['train'], mnist_dataset['test']\n",
    "\n",
    "num_validation_samples = 0.1 * mnist_info.splits['train'].num_examples\n",
    "num_validation_samples = tf.cast(num_validation_samples, tf.int64)\n",
    "\n",
    "num_test_samples = mnist_info.splits['test'].num_examples\n",
    "num_test_samples = tf.cast(num_test_samples, tf.int64)\n",
    "\n",
    "\n",
    "def scale(image, label):\n",
    "    image = tf.cast(image, tf.float32)\n",
    "    image /= 255.\n",
    "    return image, label\n",
    "\n",
    "scaled_train_and_validation_data = mnist_train.map(scale)\n",
    "\n",
    "test_data = mnist_test.map(scale)\n",
    "\n",
    "\n",
    "BUFFER_SIZE = 10000\n",
    "\n",
    "shuffled_train_and_validation_data = scaled_train_and_validation_data.shuffle(BUFFER_SIZE)\n",
    "\n",
    "validation_data = shuffled_train_and_validation_data.take(num_validation_samples)\n",
    "train_data = shuffled_train_and_validation_data.skip(num_validation_samples)\n",
    "\n",
    "\n",
    "BATCH_SIZE = 100\n",
    "\n",
    "train_data = train_data.batch(BATCH_SIZE)\n",
    "validation_data = validation_data.batch(num_validation_samples)\n",
    "test_data = test_data.batch(num_test_samples)\n",
    "\n",
    "validation_inputs, validation_targets = next(iter(validation_data))"
   ]
  },
  {
   "cell_type": "markdown",
   "metadata": {},
   "source": [
    "## Model"
   ]
  },
  {
   "cell_type": "markdown",
   "metadata": {},
   "source": [
    "### Outline the model"
   ]
  },
  {
   "cell_type": "code",
   "execution_count": 1,
   "metadata": {},
   "outputs": [
    {
     "name": "stdout",
     "output_type": "stream",
     "text": [
      "ERROR! Session/line number was not unique in database. History logging moved to new session 182\n"
     ]
    }
   ],
   "source": [
    "input_size = 784\n",
    "output_size = 10\n",
    "hidden_layer_size = 50\n",
    "\n",
    "model = tf.keras.Sequential([\n",
    "                            tf.keras.layers.Flatten(input_shape=(28,28,1)),\n",
    "                            tf.keras.layers.Dense(hidden_layer_size, activation='relu'),\n",
    "                            tf.keras.layers.Dense(hidden_layer_size, activation='relu'),\n",
    "                            tf.keras.layers.Dense(output_size, activation='softmax')   \n",
    "                            ])"
   ]
  },
  {
   "cell_type": "markdown",
   "metadata": {},
   "source": [
    "### Choose the optimizer and the loss function"
   ]
  },
  {
   "cell_type": "code",
   "execution_count": 7,
   "metadata": {},
   "outputs": [],
   "source": [
    "model.compile(optimizer='adam', loss='sparse_categorical_crossentropy', metrics=['accuracy'])"
   ]
  },
  {
   "cell_type": "markdown",
   "metadata": {},
   "source": [
    "### Training"
   ]
  },
  {
   "cell_type": "code",
   "execution_count": 8,
   "metadata": {},
   "outputs": [
    {
     "name": "stdout",
     "output_type": "stream",
     "text": [
      "Epoch 1/5\n",
      "540/540 - 6s - loss: 0.3206 - accuracy: 0.9105 - val_loss: 0.0000e+00 - val_accuracy: 0.0000e+00\n",
      "Epoch 2/5\n",
      "540/540 - 5s - loss: 0.1344 - accuracy: 0.9604 - val_loss: 0.1131 - val_accuracy: 0.9680\n",
      "Epoch 3/5\n",
      "540/540 - 5s - loss: 0.0969 - accuracy: 0.9710 - val_loss: 0.0972 - val_accuracy: 0.9745\n",
      "Epoch 4/5\n",
      "540/540 - 5s - loss: 0.0752 - accuracy: 0.9776 - val_loss: 0.0841 - val_accuracy: 0.9745\n",
      "Epoch 5/5\n",
      "540/540 - 5s - loss: 0.0609 - accuracy: 0.9812 - val_loss: 0.0681 - val_accuracy: 0.9790\n"
     ]
    },
    {
     "data": {
      "text/plain": [
       "<tensorflow.python.keras.callbacks.History at 0x229f22494a8>"
      ]
     },
     "execution_count": 8,
     "metadata": {},
     "output_type": "execute_result"
    }
   ],
   "source": [
    "NUM_EPOCHS = 5\n",
    "\n",
    "model.fit(train_data, epochs = NUM_EPOCHS, validation_data=(validation_inputs, validation_targets), verbose=2)"
   ]
  },
  {
   "cell_type": "markdown",
   "metadata": {},
   "source": [
    "## Test the model"
   ]
  },
  {
   "cell_type": "code",
   "execution_count": 9,
   "metadata": {},
   "outputs": [
    {
     "name": "stdout",
     "output_type": "stream",
     "text": [
      "      1/Unknown - 1s 1s/step - loss: 0.0897 - accuracy: 0.97 - 1s 1s/step - loss: 0.0897 - accuracy: 0.9728"
     ]
    }
   ],
   "source": [
    "test_loss, test_accuracy = model.evaluate(test_data)"
   ]
  },
  {
   "cell_type": "code",
   "execution_count": 10,
   "metadata": {},
   "outputs": [
    {
     "name": "stdout",
     "output_type": "stream",
     "text": [
      "Test loss: 0.09. Test accuracy: 97.28%\n"
     ]
    }
   ],
   "source": [
    "print('Test loss: {0:.2f}. Test accuracy: {1:.2f}%'.format(test_loss, test_accuracy*100.))"
   ]
  }
 ],
 "metadata": {
  "kernelspec": {
   "display_name": "Python [conda env:vedadri]",
   "language": "python",
   "name": "conda-env-vedadri-py"
  },
  "language_info": {
   "codemirror_mode": {
    "name": "ipython",
    "version": 3
   },
   "file_extension": ".py",
   "mimetype": "text/x-python",
   "name": "python",
   "nbconvert_exporter": "python",
   "pygments_lexer": "ipython3",
   "version": "3.7.10"
  }
 },
 "nbformat": 4,
 "nbformat_minor": 2
}
